<robot name="leo">
<!-- chassis -->
<link name="chassis">
    <inertial>
        <origin xyz="0.0 0.0 0.0" rpy="0.0 0.0 0.0"/>
        <mass value="0.0"/>
        <inertia ixx="0.0" ixy="0.0" ixz="0.0" iyy="0.0" iyz="0.0" izz="0.0"/>
    </inertial>
    <visual name="">
        <origin xyz="0.0 0.0 0.0" rpy="0.0 0.0 0.0"/>
        <geometry>
            <!-- <mesh filename="package://ugv/meshes/Chassis_outline.stl"/> -->
            <mesh filename="package://ugv/src/meshes/Chassis.dae"/>
        </geometry>
        <material name="">
            <color rgba="1.0 0.0 1.0 1.0"/>
            <texture filename=""/>
        </material>
    </visual>
    <collision>
        <origin xyz="0.0 0.0 0.0" rpy="0.0 0.0 0.0"/>
        <geometry>
            <box size="0.0 0.0 0.0"/>
        </geometry>
    </collision>
</link>

<!-- right -->

<link name="rocker_right">
    <inertial>
        <mass value="1.387336"/>
          <origin xyz="0 0.01346 -0.06506"/>
        <inertia
            ixx="0.002956" ixy="-0.000001489324" ixz="-0.000008103407"
            iyy="0.02924"  iyz="0.00007112"
            izz="0.02832"/>
    </inertial>
    <visual name="">
        <origin xyz="0.0 0.0 0.0" rpy="0.0 0.0 0.0"/>
        <geometry>
            <mesh filename="package://ugv/src/meshes/Rocker.dae"/>

        </geometry>
        <material name="">
            <color rgba="1.0 0.0 0.0 1.0"/>
            <texture filename=""/>
        </material>
    </visual>
     <collision>
          <geometry>
            <mesh filename="package://ugv/src/meshes/Rocker_outline.stl"/>
          </geometry>
        </collision>
</link>


<joint name="rocker_right_joint" type="fixed">
    <origin xyz="0 0.01346 -0.06506" rpy="0.0 0.0 0.0"/>
    <parent link="chassis"/>
    <child link="rocker_right"/>
    <axis xyz="0.0 0.0 0.0"/>
    <limit lower="0.0" upper="0.0" effort="0.0" velocity="0.0"/>
</joint>

    <!-- left -->
<link name="rocker_left">
        <inertial>
        <mass value="1.387336"/>
          <origin xyz="0 0.01346 -0.06506"/>
        <inertia
            ixx="0.002956" ixy="-0.000001489324" ixz="-0.000008103407"
            iyy="0.02924"  iyz="0.00007112"
            izz="0.02832"/>
    </inertial>
    <visual name="">
        <origin xyz="0.0 0.0 0.0" rpy="0.0 0.0 0.0"/>
        <geometry>
            <mesh filename="package://ugv/src/meshes/Rocker.dae"/>

        </geometry>
        <material name="">
            <color rgba="1.0 0.0 0.0 1.0"/>
            <texture filename=""/>
        </material>
    </visual>
    <collision>
          <geometry>
            <mesh filename="package://ugv/src/meshes/Rocker_outline.stl"/>
          </geometry>
        </collision>
</link>


<joint name="rocker_left_joint" type="fixed">
    <origin xyz="0.003 0.145 -0.045" rpy="0.0 0.0 3.14"/>
    <parent link="chassis"/>
    <child link="rocker_left"/>
    <axis xyz="0.0 0.0 0.0"/>
    <limit lower="0.0" upper="0.0" effort="0.0" velocity="0.0"/>
</joint>

<!-- wheel right front -->
<link name="wheel_right_front">
    <inertial>
          <mass value="0.283642"/>
          <origin xyz="0 0.030026 0"/>
          <inertia
            ixx="0.000391"  ixy="0.00000123962" ixz="5.52582e-7"
            iyy="0.0004716" iyz="-0.000002082042"
            izz="0.000391"/>
        </inertial>
    <visual name="">
        <!-- <origin xyz="0.075 -0.04 -0.045" rpy="0.0 0.0 0.0"/> -->
        <origin xyz="0.0 0.0 0.0" rpy="0.0 0.0 0.0"/>
        <geometry>
          <mesh filename="package://ugv/src/meshes/WheelB.dae"/>
        </geometry>
        <material name="">
            <color rgba="1.0 0.0 0.0 1.0"/>
            <texture filename=""/>
        </material>
    </visual>
  <collision>
          <origin xyz="0 0.04485 0" rpy="1.57 0 0"/>
          <geometry>
            <cylinder radius="0.057" length="0.07"/>
          </geometry>
        </collision>
        <collision>
          <origin xyz="0 0.04485 0" rpy="1.57 0 0"/>
          <geometry>
            <cylinder radius="0.0625" length="0.04"/>
          </geometry>
        </collision>
        <collision>
          <geometry>
            <mesh filename="package://ugv/src/meshes/Wheel_outline.stl"/>
          </geometry>
        </collision>
</link>

<joint name="wheel_right_front_joint" type="continuous">
    <!-- <origin xyz="0.075 -0.04 -0.045" rpy="0.0 0.0 0.0"/> -->
    <origin xyz="0.15 -0.08 -0.09" rpy="0.0 0.0 0.0"/>
    <parent link="rocker_right"/>
    <child link="wheel_right_front"/>
    <axis xyz="0.0 1.0 0.0"/>
    <limit lower="0.0" upper="6.28" effort="0.0" velocity="0.01"/>
</joint>

<!-- wheek right back -->

<link name="wheel_right_back">
    <inertial>
          <mass value="0.283642"/>
          <origin xyz="0 0.030026 0"/>
          <inertia
            ixx="0.000391"  ixy="0.00000123962" ixz="5.52582e-7"
            iyy="0.0004716" iyz="-0.000002082042"
            izz="0.000391"/>
        </inertial>
    <visual name="">
        <!-- <origin xyz="0.075 -0.04 -0.045" rpy="0.0 0.0 0.0"/> -->
        <origin xyz="0.0 0.0 0.0" rpy="0.0 0.0 0.0"/>
        <geometry>
          <mesh filename="package://ugv/src/meshes/WheelB.dae"/>
        </geometry>
        <material name="">
            <color rgba="1.0 0.0 0.0 1.0"/>
            <texture filename=""/>
        </material>
    </visual>
    <collision>
          <origin xyz="0 0.04485 0" rpy="1.57 0 0"/>
          <geometry>
            <cylinder radius="0.057" length="0.07"/>
          </geometry>
        </collision>
        <collision>
          <origin xyz="0 0.04485 0" rpy="1.57 0 0"/>
          <geometry>
            <cylinder radius="0.0625" length="0.04"/>
          </geometry>
        </collision>
        <collision>
          <geometry>
            <mesh filename="package://ugv/src/meshes/Wheel_outline.stl"/>
          </geometry>
        </collision>
</link>

<joint name="wheel_right_back_joint" type="continuous">
    <!-- <origin xyz="0.075 -0.04 -0.045" rpy="0.0 0.0 0.0"/> -->
    <origin xyz="-0.15 -0.08 -0.09" rpy="0.0 0.0 0.0"/>
    <parent link="rocker_right"/>
    <child link="wheel_right_back"/>
    <axis xyz="0.0 1.0 0.0"/>
    <limit lower="0.0" upper="6.28" effort="0.0" velocity="0.01"/>
</joint>
<!-- wheel left front -->

<link name="wheel_left_front">
    <inertial>
          <mass value="0.283642"/>
          <origin xyz="0 0.030026 0"/>
          <inertia
            ixx="0.000391"  ixy="0.00000123962" ixz="5.52582e-7"
            iyy="0.0004716" iyz="-0.000002082042"
            izz="0.000391"/>
        </inertial>
    <visual name="">
        <!-- <origin xyz="0.075 -0.04 -0.045" rpy="0.0 0.0 0.0"/> -->
        <origin xyz="0.0 0.0 0.0" rpy="0.0 0.0 0.0"/>
        <geometry>
          <mesh filename="package://ugv/src/meshes/WheelA.dae"/>
        </geometry>
        <material name="">
            <color rgba="1.0 0.0 0.0 1.0"/>
            <texture filename=""/>
        </material>
    </visual>
    <collision>
          <origin xyz="0 0.04485 0" rpy="1.57 0 0"/>
          <geometry>
            <cylinder radius="0.057" length="0.07"/>
          </geometry>
        </collision>
        <collision>
          <origin xyz="0 0.04485 0" rpy="1.57 0 0"/>
          <geometry>
            <cylinder radius="0.0625" length="0.04"/>
          </geometry>
        </collision>
        <collision>
          <geometry>
            <mesh filename="package://ugv/src/meshes/Wheel_outline.stl"/>
          </geometry>
        </collision>
</link>

<joint name="wheel_left_front_joint" type="continuous">
    <!-- <origin xyz="0.075 -0.04 -0.045" rpy="0.0 0.0 0.0"/> -->
    <origin xyz="0.15 -0.08 -0.09" rpy="0.0 0.0 0.0"/>
    <parent link="rocker_left"/>
    <child link="wheel_left_front"/>
    <axis xyz="0.0 1.0 0.0"/>
    <limit lower="0.0" upper="6.28" effort="0.0" velocity="0.01"/>
</joint>

<!-- wheel left back -->

<link name="wheel_left_back">
   <inertial>
          <mass value="0.283642"/>
          <origin xyz="0 0.030026 0"/>
          <inertia
            ixx="0.000391"  ixy="0.00000123962" ixz="5.52582e-7"
            iyy="0.0004716" iyz="-0.000002082042"
            izz="0.000391"/>
        </inertial>
    <visual name="">
        <!-- <origin xyz="0.075 -0.04 -0.045" rpy="0.0 0.0 0.0"/> -->
        <origin xyz="0.0 0.0 0.0" rpy="0.0 0.0 0.0"/>
        <geometry>
          <mesh filename="package://ugv/src/meshes/WheelA.dae"/>
        </geometry>
        <material name="">
            <color rgba="1.0 0.0 0.0 1.0"/>
            <texture filename=""/>
        </material>
    </visual>
    <collision>
          <origin xyz="0 0.04485 0" rpy="1.57 0 0"/>
          <geometry>
            <cylinder radius="0.057" length="0.07"/>
          </geometry>
        </collision>
        <collision>
          <origin xyz="0 0.04485 0" rpy="1.57 0 0"/>
          <geometry>
            <cylinder radius="0.0625" length="0.04"/>
          </geometry>
        </collision>
        <collision>
          <geometry>
            <mesh filename="package://ugv/src/meshes/Wheel_outline.stl"/>
          </geometry>
        </collision>
</link>

<joint name="wheel_left_back_joint" type="continuous">
    <!-- <origin xyz="0.075 -0.04 -0.045" rpy="0.0 0.0 0.0"/> -->
    <origin xyz="-0.15 -0.08 -0.09" rpy="0.0 0.0 0.0"/>
    <parent link="rocker_left"/>
    <child link="wheel_left_back"/>
    <axis xyz="0.0 1.0 0.0"/>
    <limit lower="0.0" upper="6.28" effort="0.0" velocity="0.01"/>
</joint>


   <gazebo reference="chassis">
      <kp>1e6</kp>
      <kd>1.0</kd>
      <mu1>0.3</mu1>
      <mu2>0.3</mu2>
      <minDepth>0.003</minDepth>
    </gazebo>

    <!-- <gazebo reference="">
      <kp>1e6</kp>
      <kd>1.0</kd>
      <mu1>0.3</mu1>
      <mu2>0.3</mu2>
      <minDepth>0.003</minDepth>
    </gazebo> -->

    <!-- rocker ODE properties -->
    <gazebo reference="rocker_right">
      <kp>1e6</kp>
      <kd>1.0</kd>
      <mu1>0.3</mu1>
      <mu2>0.3</mu2>
      <minDepth>0.003</minDepth>
    </gazebo>

    <gazebo reference="rocker_left">
      <kp>1e6</kp>
      <kd>1.0</kd>
      <mu1>0.3</mu1>
      <mu2>0.3</mu2>
      <minDepth>0.003</minDepth>
    </gazebo>
    <!-- wheel ODE properties -->

    <gazebo reference="wheel_right_front">
      <kp>1e6</kp>
      <kd>100.0</kd>
      <mu1>3.0</mu1>
      <mu2>1.0</mu2>
      <fdir1>1 0 0</fdir1>
      <minDepth>0.003</minDepth>
    </gazebo>

    <gazebo reference="wheel_right_back">
      <kp>1e6</kp>
      <kd>100.0</kd>
      <mu1>3.0</mu1>
      <mu2>1.0</mu2>
      <fdir1>1 0 0</fdir1>
      <minDepth>0.003</minDepth>
    </gazebo>

    <gazebo reference="wheel_left_front">
      <kp>1e6</kp>
      <kd>100.0</kd>
      <mu1>3.0</mu1>
      <mu2>1.0</mu2>
      <fdir1>1 0 0</fdir1>
      <minDepth>0.003</minDepth>
    </gazebo>

    <gazebo reference="wheel_left_back">
      <kp>1e6</kp>
      <kd>100.0</kd>
      <mu1>3.0</mu1>
      <mu2>1.0</mu2>
      <fdir1>1 0 0</fdir1>
      <minDepth>0.003</minDepth>
    </gazebo>

       <!-- rocker differential -->
    <gazebo>
      <plugin name="differential_drive_controller"
          filename="libgazebo_ros_diff_drive.so">
      <leftJoint>wheel_left_back_joint</leftJoint>
      <rightJoint>wheel_right_back_joint</rightJoint>
      <legacyMode>false</legacyMode>
      
      <robotbase_footprintFrame>chassis</robotbase_footprintFrame>
      <wheelSeparation>0.3</wheelSeparation>
      <wheelDiameter>0.07</wheelDiameter>
      <publishWheelJointState>true</publishWheelJointState>
  </plugin>
    </gazebo>


</robot>