<robot name="leo">
<!-- chassis -->
<link name="chassis">
    <inertial>
        <origin xyz="0.0 0.0 0.0" rpy="0.0 0.0 0.0"/>
        <mass value="0.0"/>
        <inertia ixx="0.0" ixy="0.0" ixz="0.0" iyy="0.0" iyz="0.0" izz="0.0"/>
    </inertial>
    <visual name="">
        <origin xyz="0.0 0.0 0.0" rpy="0.0 0.0 0.0"/>
        <geometry>
            <!-- <mesh filename="package://ugv/meshes/Chassis_outline.stl"/> -->
            <mesh filename="package://ugv/src/meshes/Chassis.dae"/>
        </geometry>
        <material name="">
            <color rgba="1.0 0.0 1.0 1.0"/>
            <texture filename=""/>
        </material>
    </visual>
    <collision>
        <origin xyz="0.0 0.0 0.0" rpy="0.0 0.0 0.0"/>
        <geometry>
            <box size="0.0 0.0 0.0"/>
        </geometry>
    </collision>
</link>

<!-- right -->

<link name="rocker_right">
    <inertial>
        <mass value="1.387336"/>
          <origin xyz="0 0.01346 -0.06506"/>
        <inertia
            ixx="0.002956" ixy="-0.000001489324" ixz="-0.000008103407"
            iyy="0.02924"  iyz="0.00007112"
            izz="0.02832"/>
    </inertial>
    <visual name="">
        <origin xyz="0.0 0.0 0.0" rpy="0.0 0.0 0.0"/>
        <geometry>
            <mesh filename="package://ugv/src/meshes/Rocker.dae"/>

        </geometry>
        <material name="">
            <color rgba="1.0 0.0 0.0 1.0"/>
            <texture filename=""/>
        </material>
    </visual>
     <collision>
          <geometry>
            <mesh filename="package://ugv/src/meshes/Rocker_outline.stl"/>
          </geometry>
        </collision>
</link>


<joint name="rocker_right_joint" type="fixed">
    <origin xyz="0.003 -0.145 -0.045" rpy="0.0 0.0 0.0"/>
    <parent link="chassis"/>
    <child link="rocker_right"/>
    <axis xyz="0.0 0.0 0.0"/>
    <limit lower="0.0" upper="0.0" effort="0.0" velocity="0.0"/>
</joint>

    <!-- left -->
<link name="rocker_left">
        <inertial>
        <mass value="1.387336"/>
          <origin xyz="0 0.01346 -0.06506"/>
        <inertia
            ixx="0.002956" ixy="-0.000001489324" ixz="-0.000008103407"
            iyy="0.02924"  iyz="0.00007112"
            izz="0.02832"/>
    </inertial>
    <visual name="">
        <origin xyz="0.0 0.0 0.0" rpy="0.0 0.0 0.0"/>
        <geometry>
            <mesh filename="package://ugv/src/meshes/Rocker.dae"/>

        </geometry>
        <material name="">
            <color rgba="1.0 0.0 0.0 1.0"/>
            <texture filename=""/>
        </material>
    </visual>
    <collision>
          <geometry>
            <mesh filename="package://ugv/src/meshes/Rocker_outline.stl"/>
          </geometry>
        </collision>
</link>


<joint name="rocker_left_joint" type="fixed">
    <origin xyz="0.003 0.145 -0.045" rpy="0.0 0.0 3.14"/>
    <parent link="chassis"/>
    <child link="rocker_left"/>
    <axis xyz="0.0 0.0 0.0"/>
    <limit lower="0.0" upper="0.0" effort="0.0" velocity="0.0"/>
</joint>

<!-- wheel right front -->
<link name="wheel_right_front">
    <inertial>
          <mass value="0.283642"/>
          <origin xyz="0 0.030026 0"/>
          <inertia
            ixx="0.000391"  ixy="0.00000123962" ixz="5.52582e-7"
            iyy="0.0004716" iyz="-0.000002082042"
            izz="0.000391"/>
        </inertial>
    <visual name="">
        <!-- <origin xyz="0.075 -0.04 -0.045" rpy="0.0 0.0 0.0"/> -->
        <origin xyz="0.0 0.0 0.0" rpy="0.0 0.0 0.0"/>
        <geometry>
          <mesh filename="package://ugv/src/meshes/WheelB.dae"/>
        </geometry>
        <material name="">
            <color rgba="1.0 0.0 0.0 1.0"/>
            <texture filename=""/>
        </material>
    </visual>
  <collision>
          <origin xyz="0 0.04485 0" rpy="1.57 0 0"/>
          <geometry>
            <cylinder radius="0.057" length="0.07"/>
          </geometry>
        </collision>
        <collision>
          <origin xyz="0 0.04485 0" rpy="1.57 0 0"/>
          <geometry>
            <cylinder radius="0.0625" length="0.04"/>
          </geometry>
        </collision>
        <collision>
          <geometry>
            <mesh filename="package://ugv/src/meshes/Wheel_outline.stl"/>
          </geometry>
        </collision>
</link>

<joint name="wheel_right_front_joint" type="continuous">
    <!-- <origin xyz="0.075 -0.04 -0.045" rpy="0.0 0.0 0.0"/> -->
   <origin xyz="0.15256 -0.08214 -0.08802" rpy="0 0 0"/>
    <parent link="rocker_right"/>
    <child link="wheel_right_front"/>
    <axis xyz="0.0 1.0 0.0"/>
   <limit effort="2.0" velocity="6.0"/>
      <dynamics friction="0.3125" damping="0.1"/>
</joint>

<!-- wheek right back -->

<link name="wheel_right_back">
    <inertial>
          <mass value="0.283642"/>
          <origin xyz="0 0.030026 0"/>
          <inertia
            ixx="0.000391"  ixy="0.00000123962" ixz="5.52582e-7"
            iyy="0.0004716" iyz="-0.000002082042"
            izz="0.000391"/>
        </inertial>
    <visual name="">
        <!-- <origin xyz="0.075 -0.04 -0.045" rpy="0.0 0.0 0.0"/> -->
        <origin xyz="0.0 0.0 0.0" rpy="0.0 0.0 0.0"/>
        <geometry>
          <mesh filename="package://ugv/src/meshes/WheelB.dae"/>
        </geometry>
        <material name="">
            <color rgba="1.0 0.0 0.0 1.0"/>
            <texture filename=""/>
        </material>
    </visual>
    <collision>
          <origin xyz="0 0.04485 0" rpy="1.57 0 0"/>
          <geometry>
            <cylinder radius="0.057" length="0.07"/>
          </geometry>
        </collision>
        <collision>
          <origin xyz="0 0.04485 0" rpy="1.57 0 0"/>
          <geometry>
            <cylinder radius="0.0625" length="0.04"/>
          </geometry>
        </collision>
        <collision>
          <geometry>
            <mesh filename="package://ugv/src/meshes/Wheel_outline.stl"/>
          </geometry>
        </collision>
</link>

<joint name="wheel_right_back_joint" type="revolute">
    <!-- <origin xyz="0.075 -0.04 -0.045" rpy="0.0 0.0 0.0"/> -->
     <origin xyz="-0.15256 -0.08214 -0.08802" rpy="0 0 0"/>
    <parent link="rocker_right"/>
    <child link="wheel_right_back"/>
      <axis xyz="0 1 0"/>
      <limit effort="2.0" velocity="6.0"/>
      <dynamics friction="0.3125" damping="0.1"/> 
</joint>
<!-- wheel left front -->

<link name="wheel_left_front">
    <inertial>
          <mass value="0.283642"/>
          <origin xyz="0 0.030026 0"/>
          <inertia
            ixx="0.000391"  ixy="0.00000123962" ixz="5.52582e-7"
            iyy="0.0004716" iyz="-0.000002082042"
            izz="0.000391"/>
        </inertial>
    <visual name="">
        <!-- <origin xyz="0.075 -0.04 -0.045" rpy="0.0 0.0 0.0"/> -->
        <origin xyz="0.0 0.0 0.0" rpy="0.0 0.0 0.0"/>
        <geometry>
          <mesh filename="package://ugv/src/meshes/WheelB.dae"/>
        </geometry>
        <material name="">
            <color rgba="1.0 0.0 0.0 1.0"/>
            <texture filename=""/>
        </material>
    </visual>
    <collision>
          <origin xyz="0 0.04485 0" rpy="1.57 0 0"/>
          <geometry>
            <cylinder radius="0.057" length="0.07"/>
          </geometry>
        </collision>
        <collision>
          <origin xyz="0 0.04485 0" rpy="1.57 0 0"/>
          <geometry>
            <cylinder radius="0.0625" length="0.04"/>
          </geometry>
        </collision>
        <collision>
          <geometry>
            <mesh filename="package://ugv/src/meshes/Wheel_outline.stl"/>
          </geometry>
        </collision>
</link>

<joint name="wheel_left_front_joint" type="continuous">
    <!-- <origin xyz="0.075 -0.04 -0.045" rpy="0.0 0.0 0.0"/> -->
     <origin xyz="-0.15256 -0.08214 -0.08802" rpy="0 0 0"/>
    <parent link="rocker_left"/>
    <child link="wheel_left_front"/>
      <axis xyz="0 -1 0"/>
      <limit effort="2.0" velocity="6.0"/>
      <dynamics friction="0.3125" damping="0.1"/>
</joint>

<!-- wheel left back -->

<link name="wheel_left_back">
   <inertial>
          <mass value="0.283642"/>
          <origin xyz="0 0.030026 0"/>
          <inertia
            ixx="0.000391"  ixy="0.00000123962" ixz="5.52582e-7"
            iyy="0.0004716" iyz="-0.000002082042"
            izz="0.000391"/>
        </inertial>
    <visual name="">
        <!-- <origin xyz="0.075 -0.04 -0.045" rpy="0.0 0.0 0.0"/> -->
        <origin xyz="0.0 0.0 0.0" rpy="0.0 0.0 0.0"/>
        <geometry>
          <mesh filename="package://ugv/src/meshes/WheelB.dae"/>
        </geometry>
        <material name="">
            <color rgba="1.0 0.0 0.0 1.0"/>
            <texture filename=""/>
        </material>
    </visual>
    <collision>
          <origin xyz="0 0.04485 0" rpy="1.57 0 0"/>
          <geometry>
            <cylinder radius="0.057" length="0.07"/>
          </geometry>
        </collision>
        <collision>
          <origin xyz="0 0.04485 0" rpy="1.57 0 0"/>
          <geometry>
            <cylinder radius="0.0625" length="0.04"/>
          </geometry>
        </collision>
        <collision>
          <geometry>
            <mesh filename="package://ugv/src/meshes/Wheel_outline.stl"/>
          </geometry>
        </collision>
</link>

<joint name="wheel_left_back_joint" type="revolute">
    <!-- <origin xyz="0.075 -0.04 -0.045" rpy="0.0 0.0 0.0"/> -->
      <origin xyz="0.15256 -0.08214 -0.08802" rpy="0 0 0"/>
    <parent link="rocker_left"/>
    <child link="wheel_left_back"/>
      <axis xyz="0 -1 0"/>
      <limit effort="2.0" velocity="6.0"/>
      <dynamics friction="0.3125" damping="0.1"/>
</joint>

<!-- camera -->

  <link name="camera_frame"/>
    <link name="camera_optical_frame"/>
    <link name="imu_frame"/> 

        <joint name="camera_joint" type="fixed">
      <origin xyz="0.0971 0 -0.0427" rpy="0 0.2094 0"/>
      <parent link="chassis"/>
      <child link="camera_frame"/>
    </joint>

    <joint name="camera_optical_joint" type="fixed">
      <origin xyz="0 0 0" rpy="-1.57 0.0 -1.57"/>
      <parent link="camera_frame"/>
      <child link="camera_optical_frame"/>
    </joint>

    <joint name="imu_joint" type="fixed">
      <origin xyz="0.0628 -0.0314 -0.0393" rpy="0 0 0"/>
      <parent link="chassis"/>
      <child link="imu_frame"/>
    </joint>


<!-- gazebo -->
   <gazebo reference="chassis">
      <kp>1e6</kp>
      <kd>1.0</kd>
      <mu1>0.3</mu1>
      <mu2>0.3</mu2>
      <minDepth>0.003</minDepth>
    </gazebo>

    <!-- <gazebo reference="">
      <kp>1e6</kp>
      <kd>1.0</kd>
      <mu1>0.3</mu1>
      <mu2>0.3</mu2>
      <minDepth>0.003</minDepth>
    </gazebo> -->

    <!-- rocker ODE properties -->
    <gazebo reference="rocker_right">
      <kp>1e6</kp>
      <kd>1.0</kd>
      <mu1>0.3</mu1>
      <mu2>0.3</mu2>
      <minDepth>0.003</minDepth>
    </gazebo>

    <gazebo reference="rocker_left">
      <kp>1e6</kp>
      <kd>1.0</kd>
      <mu1>0.3</mu1>
      <mu2>0.3</mu2>
      <minDepth>0.003</minDepth>
    </gazebo>
    <!-- wheel ODE properties -->

    <gazebo reference="wheel_right_front">
      <kp>1e6</kp>
      <kd>100.0</kd>
      <mu1>3.0</mu1>
      <mu2>1.0</mu2>
      <fdir1>1 0 0</fdir1>
      <minDepth>0.003</minDepth>
    </gazebo>

    <gazebo reference="wheel_right_back">
      <kp>1e6</kp>
      <kd>100.0</kd>
      <mu1>3.0</mu1>
      <mu2>1.0</mu2>
      <fdir1>1 0 0</fdir1>
      <minDepth>0.003</minDepth>
    </gazebo>

    <gazebo reference="wheel_left_front">
      <kp>1e6</kp>
      <kd>100.0</kd>
      <mu1>3.0</mu1>
      <mu2>1.0</mu2>
      <fdir1>1 0 0</fdir1>
      <minDepth>0.003</minDepth>
    </gazebo>

    <gazebo reference="wheel_left_back">
      <kp>1e6</kp>
      <kd>100.0</kd>
      <mu1>3.0</mu1>
      <mu2>1.0</mu2>
      <fdir1>1 0 0</fdir1>
      <minDepth>0.003</minDepth>
    </gazebo>

       <!-- rocker differential -->
    <gazebo>
      <plugin name="differential_drive_controller"
          filename="libgazebo_ros_diff_drive.so">
      <leftJoint>wheel_left_front_joint</leftJoint>
      <rightJoint>wheel_right_front_joint</rightJoint>
      <legacyMode>false</legacyMode>
      
      <robotbase_footprintFrame>chassis</robotbase_footprintFrame>
      <wheelSeparation>0.3</wheelSeparation>
      <wheelDiameter>0.07</wheelDiameter>
      <publishWheelJointState>true</publishWheelJointState>
  </plugin>
    </gazebo>

<!-- camera -->
<gazebo reference="camera_frame">
      <sensor type="camera" name="camera">
        <always_on>true</always_on>
        <update_rate>30.0</update_rate>
        <visualize>false</visualize> 
        <camera name="camera">
          <horizontal_fov>1.9</horizontal_fov>
          <image>
            <width>640</width>
            <height>480</height>
            <format>R8G8B8</format>
          </image>
          <clip>
            <near>0.02</near>
            <far>300</far>
          </clip>
          <noise>
            <type>gaussian</type>
            <mean>0.0</mean>
            <stddev>0.007</stddev>
          </noise>
          <distortion>
            <k1>-0.279817</k1>
            <k2>0.060321</k2>
            <k3>0.000487</k3>
            <p1>0.000310</p1>
            <p2>0.000000</p2>
            <center>0.5 0.5</center>
          </distortion>
        </camera>
        <plugin name="camera_controller" filename="libgazebo_ros_camera.so">
          <robotNamespace>/</robotNamespace>
          <cameraName>camera</cameraName>
          <imageTopicName>image_raw</imageTopicName>
          <cameraInfoTopicName>camera_info</cameraInfoTopicName>
          <frameName>camera_optical_frame</frameName>
          <distortionK1>-0.279817</distortionK1>
          <distortionK2>0.060321</distortionK2>
          <distortionK3>0.000487</distortionK3>
          <distortionT1>0.000310</distortionT1>
          <distortionT2>0.000000</distortionT2>
        </plugin>
      </sensor>
    </gazebo>


        <gazebo reference="imu_frame">
      <sensor type="imu" name="imu_sensor">
        <update_rate>100</update_rate>
        <plugin filename="libgazebo_ros_imu_sensor.so" name="imu_plugin">
          <robotNamespace>/</robotNamespace>
          <topicName>imu/data_raw</topicName>
          <frameName>imu_frame</frameName>
          <updateRateHZ>100.0</updateRateHZ>
          <gaussianNoise>0.01</gaussianNoise>
          <initialOrientationAsReference>false</initialOrientationAsReference>
        </plugin>
      </sensor>
    </gazebo>


</robot>